<robot
  name="archie_description">
  <link name="base_link"/>
  <link
    name="base">
    <inertial>
      <origin
        xyz="0.0152830659077714 0.00540039654606211 0.0772732355708442"
        rpy="0 0 0" />
      <mass
        value="2.03702160122731" />
      <inertia
        ixx="0.0700076291523445"
        ixy="0.00173252522409421"
        ixz="0.0102580737433572"
        iyy="0.0759066905708362"
        iyz="0.000868955518701689"
        izz="0.0392243111048869" />
    </inertial>
    <visual>
      <origin
        xyz="0 0 0"
        rpy="0 0 0" />
      <geometry>
        <mesh
          filename="package://archie_description/meshes/base.STL" />
      </geometry>
      <material
        name="">
        <color
          rgba="0.792156862745098 0.819607843137255 0.933333333333333 1" />
      </material>
    </visual>
    <collision>
      <origin
        xyz="0 0 0"
        rpy="0 0 0" />
      <geometry>
        <mesh
          filename="package://archie_description/meshes/base.STL" />
      </geometry>
    </collision>
  </link>
  <joint
    name="base_joint"
    type="fixed">
    <origin
      xyz="0 0 0.0549"
      rpy="-0.00042319083381432 -1.21232042851455E-17 -2.84597815903914E-14" />
    <parent
      link="base_link" />
    <child
      link="base" />
    <axis
      xyz="0 0 0" />
  </joint>
  <link
    name="lidar">
    <inertial>
      <origin
        xyz="0.0119189346934023 -0.000416352072927687 -0.0147703105325154"
        rpy="0 0 0" />
      <mass
        value="0.0735157357198281" />
      <inertia
        ixx="2.97357906825751E-05"
        ixy="-5.26807920686531E-07"
        ixz="9.41977601900913E-06"
        iyy="5.97754355572045E-05"
        iyz="2.66364043992351E-07"
        izz="6.82720051792446E-05" />
    </inertial>
    <visual>
      <origin
        xyz="0 0 0"
        rpy="0 0 0" />
      <geometry>
        <mesh
          filename="package://archie_description/meshes/lidar.STL" />
      </geometry>
      <material
        name="">
        <color
          rgba="0.792156862745098 0.819607843137255 0.933333333333333 1" />
      </material>
    </visual>
    <collision>
      <origin
        xyz="0 0 0"
        rpy="0 0 0" />
      <geometry>
        <mesh
          filename="package://archie_description/meshes/lidar.STL" />
      </geometry>
    </collision>
  </link>
  <joint
    name="lidar_joint"
    type="fixed">
    <origin
      xyz="0.219 -1.00719415356276E-05 0.0237999978688232"
      rpy="-7.92848647505339E-20 0.00042319083381432 -1.57079632679487" />
    <parent
      link="base" />
    <child
      link="lidar" />
    <axis
      xyz="0 0 0" />
  </joint>
  <link
    name="right_wheel">
    <inertial>
      <origin
        xyz="-8.53355384065613E-05 0.00230829105658384 1.57153402591814E-05"
        rpy="0 0 0" />
      <mass
        value="0.187715234825624" />
      <inertia
        ixx="0.000202585219170499"
        ixy="-1.42815369425292E-09"
        ixz="-1.20829539485632E-07"
        iyy="0.000370271049787534"
        iyz="2.23782609841976E-10"
        izz="0.00020181360809056" />
    </inertial>
    <visual>
      <origin
        xyz="0 0 0"
        rpy="0 0 0" />
      <geometry>
        <mesh
          filename="package://archie_description/meshes/right_wheel.STL" />
      </geometry>
      <material
        name="">
        <color
          rgba="0.294117647058824 0.294117647058824 0.294117647058824 1" />
      </material>
    </visual>
    <collision>
      <origin
        xyz="0 0 0"
        rpy="0 0 0" />
      <geometry>
        <mesh
          filename="package://archie_description/meshes/right_wheel.STL" />
      </geometry>
    </collision>
  </link>
  <joint
    name="right_wheel_joint"
    type="continuous">
    <origin
      xyz="0 -0.23 0"
      rpy="0.00042319083381432 -2.68613784773866E-17 9.21205716330717E-14" />
    <parent
      link="base" />
    <child
      link="right_wheel" />
    <axis
      xyz="0 0.99999991045476 -0.00042319082118275" />
  </joint>
  <link
    name="left_wheel">
    <inertial>
      <origin
        xyz="8.53355384062282E-05 -0.00230829105658181 1.03831180030822E-05"
        rpy="0 0 0" />
      <mass
        value="0.187715234825625" />
      <inertia
        ixx="0.000202585219170499"
        ixy="-1.42815369422969E-09"
        ixz="1.20829539485635E-07"
        iyy="0.000370271049787534"
        iyz="-2.23782609806456E-10"
        izz="0.000201813608090561" />
    </inertial>
    <visual>
      <origin
        xyz="0 0 0"
        rpy="0 0 0" />
      <geometry>
        <mesh
          filename="package://archie_description/meshes/left_wheel.STL" />
      </geometry>
      <material
        name="">
        <color
          rgba="0.294117647058824 0.294117647058824 0.294117647058824 1" />
      </material>
    </visual>
    <collision>
      <origin
        xyz="0 0 0"
        rpy="0 0 0" />
      <geometry>
        <mesh
          filename="package://archie_description/meshes/left_wheel.STL" />
      </geometry>
    </collision>
  </link>
  <joint
    name="left_wheel_joint"
    type="continuous">
    <origin
      xyz="0 0.23 0"
      rpy="0.00042319083381432 9.39672386974239E-20 2.84250897059694E-14" />
    <parent
      link="base" />
    <child
      link="left_wheel" />
    <axis
      xyz="0 0.99999991045476 -0.00042319082118275" />
  </joint>
  <link
    name="camera_tilt">
    <inertial>
      <origin
        xyz="-0.00762019304628797 0.000468604856313337 0.040126487850928"
        rpy="0 0 0" />
      <mass
        value="0.0840366109601249" />
      <inertia
        ixx="0.000143438853205635"
        ixy="3.23573045912139E-07"
        ixz="2.06094905326448E-05"
        iyy="9.07581348237213E-05"
        iyz="-1.99624525894132E-07"
        izz="8.82552096758467E-05" />
    </inertial>
    <visual>
      <origin
        xyz="0 0 0"
        rpy="0 0 0" />
      <geometry>
        <mesh
          filename="package://archie_description/meshes/camera_tilt.STL" />
      </geometry>
      <material
        name="">
        <color
          rgba="0.792156862745098 0.819607843137255 0.933333333333333 1" />
      </material>
    </visual>
    <collision>
      <origin
        xyz="0 0 0"
        rpy="0 0 0" />
      <geometry>
        <mesh
          filename="package://archie_description/meshes/camera_tilt.STL" />
      </geometry>
    </collision>
  </link>
  <joint
    name="camera_tilt_joint"
    type="revolute">
    <origin
      xyz="-0.0640000000000006 -0.000263058437239949 0.621607087195183"
      rpy="0.000423190833828422 -8.4596977843948E-17 2.87905309708803E-14" />
    <parent
      link="base" />
    <child
      link="camera_tilt" />
    <axis
      xyz="0 1 0" />
    <limit
      lower="-1.5708"
      upper="1.5708"
      effort="1.2"
      velocity="5.236" />
  </joint>
  <link
    name="camera">
    <inertial>
      <origin
        xyz="0.00286762304627908 5.89571221623064E-05 0.0145825271049558"
        rpy="0 0 0" />
      <mass
        value="0.0548652828163312" />
      <inertia
        ixx="6.99395203563963E-05"
        ixy="-9.65763585635665E-08"
        ixz="3.2114605667335E-08"
        iyy="6.26127942962351E-06"
        iyz="1.95459232604844E-09"
        izz="6.88438963535692E-05" />
    </inertial>
    <visual>
      <origin
        xyz="0 0 0"
        rpy="0 0 0" />
      <geometry>
        <mesh
          filename="package://archie_description/meshes/camera.STL" />
      </geometry>
      <material
        name="">
        <color
          rgba="0.792156862745098 0.819607843137255 0.933333333333333 1" />
      </material>
    </visual>
    <collision>
      <origin
        xyz="0 0 0"
        rpy="0 0 0" />
      <geometry>
        <mesh
          filename="package://archie_description/meshes/camera.STL" />
      </geometry>
    </collision>
  </link>
  <joint
    name="camera_joint"
    type="fixed">
    <origin
      xyz="-0.0117733917670526 0 0.0721999999999999"
      rpy="-5.7211217258985E-18 -1.89949332189128E-30 -3.31395851728883E-13" />
    <parent
      link="camera_tilt" />
    <child
      link="camera" />
    <axis
      xyz="0 0 0" />
  </joint>
</robot>