<robot
  name="archie_description">
  <link
    name="base_link">
  </link>
  <link
    name="base">
    <inertial>
      <origin
        xyz="0.00733453928201211 0.00515194891324405 0.0600590776385257"
        rpy="0 0 0" />
      <mass
        value="2.31119340602887" />
      <inertia
        ixx="0.0820365921519234"
        ixy="0.00145402442171753"
        ixz="0.00779736449789006"
        iyy="0.0655678562763293"
        iyz="0.000717742863308553"
        izz="0.055720058769593" />
    </inertial>
    <visual>
      <origin
        xyz="0 0 0"
        rpy="0 0 0" />
      <geometry>
        <mesh
          filename="package://archie_description/meshes/base.STL" />
      </geometry>
      <material
        name="">
        <color
          rgba="0.752941176470588 0.752941176470588 0.752941176470588 1" />
      </material>
    </visual>
    <collision>
      <origin
        xyz="0 0 0"
        rpy="0 0 0" />
      <geometry>
        <mesh
          filename="package://archie_description/meshes/base.STL" />
      </geometry>
    </collision>
  </link>
  <joint
    name="base_joint"
    type="fixed">
    <origin
      xyz="0 0 0.0549"
      rpy="-0.00042319083381432 -1.21232042851455E-17 -2.84597815903914E-14" />
    <parent
      link="base_link" />
    <child
      link="base" />
    <axis
      xyz="0 0 0" />
  </joint>
  <link
    name="left_wheel">
    <inertial>
      <origin
        xyz="8.53355384062282E-05 -0.00230829105658181 1.03831180030822E-05"
        rpy="0 0 0" />
      <mass
        value="0.187715234825625" />
      <inertia
        ixx="0.000202585219170499"
        ixy="-1.42815369422969E-09"
        ixz="1.20829539485635E-07"
        iyy="0.000370271049787534"
        iyz="-2.23782609806456E-10"
        izz="0.000201813608090561" />
    </inertial>
    <visual>
      <origin
        xyz="0 0 0"
        rpy="0 0 0" />
      <geometry>
        <mesh
          filename="package://archie_description/meshes/left_wheel.STL" />
      </geometry>
      <material
        name="">
        <color
          rgba="0.294117647058824 0.294117647058824 0.294117647058824 1" />
      </material>
    </visual>
    <collision>
      <origin
        xyz="0 0 0"
        rpy="0 0 0" />
      <geometry>
        <mesh
          filename="package://archie_description/meshes/left_wheel.STL" />
      </geometry>
    </collision>
  </link>
  <joint
    name="left_wheel_joint"
    type="fixed">
    <origin
      xyz="0 0.23 0"
      rpy="0.00042319083381432 9.39672386974239E-20 2.84250897059694E-14" />
    <parent
      link="base" />
    <child
      link="left_wheel" />
    <axis
      xyz="0 0 0" />
  </joint>
  <link
    name="right_wheel">
    <inertial>
      <origin
        xyz="-8.53355384065613E-05 0.00230829105658387 1.57153402591537E-05"
        rpy="0 0 0" />
      <mass
        value="0.187715234825624" />
      <inertia
        ixx="0.000202585219170499"
        ixy="-1.42815369425293E-09"
        ixz="-1.20829539485632E-07"
        iyy="0.000370271049787534"
        iyz="2.23782609841977E-10"
        izz="0.00020181360809056" />
    </inertial>
    <visual>
      <origin
        xyz="0 0 0"
        rpy="0 0 0" />
      <geometry>
        <mesh
          filename="package://archie_description/meshes/right_wheel.STL" />
      </geometry>
      <material
        name="">
        <color
          rgba="0.294117647058824 0.294117647058824 0.294117647058824 1" />
      </material>
    </visual>
    <collision>
      <origin
        xyz="0 0 0"
        rpy="0 0 0" />
      <geometry>
        <mesh
          filename="package://archie_description/meshes/right_wheel.STL" />
      </geometry>
    </collision>
  </link>
  <joint
    name="right_wheel_joint"
    type="continuous">
    <origin
      xyz="0 -0.23 0"
      rpy="0.00042319083381432 -2.68613784773866E-17 9.21205716330717E-14" />
    <parent
      link="base" />
    <child
      link="right_wheel" />
    <axis
      xyz="0 0.99999991045476 -0.00042319082118275" />
  </joint>
  <link
    name="lidar">
    <inertial>
      <origin
        xyz="0.0119189312284075 -0.000416345790583944 -0.014770311626675"
        rpy="0 0 0" />
      <mass
        value="0.0735157407518519" />
      <inertia
        ixx="2.97357868328591E-05"
        ixy="-5.26803442400641E-07"
        ixz="9.41977428915003E-06"
        iyy="5.97754418539939E-05"
        iyz="2.66365610700581E-07"
        izz="6.8272006613991E-05" />
    </inertial>
    <visual>
      <origin
        xyz="0 0 0"
        rpy="0 0 0" />
      <geometry>
        <mesh
          filename="package://archie_description/meshes/lidar.STL" />
      </geometry>
      <material
        name="">
        <color
          rgba="0.752941176470588 0.752941176470588 0.752941176470588 1" />
      </material>
    </visual>
    <collision>
      <origin
        xyz="0 0 0"
        rpy="0 0 0" />
      <geometry>
        <mesh
          filename="package://archie_description/meshes/lidar.STL" />
      </geometry>
    </collision>
  </link>
  <joint
    name="lidar_joint"
    type="fixed">
    <origin
      xyz="0.219 -1.00719415356276E-05 0.0237999978688232"
      rpy="-7.92848647505339E-20 0.00042319083381432 -1.57079632679487" />
    <parent
      link="base" />
    <child
      link="lidar" />
    <axis
      xyz="0 0 0" />
  </joint>
  <link
    name="camera_tilt">
    <inertial>
      <origin
        xyz="0.0288618063642319 -5.96959703891287E-11 0.0114042265638415"
        rpy="0 0 0" />
      <mass
        value="0.0217393031475654" />
      <inertia
        ixx="2.55450729458819E-05"
        ixy="1.01285402595985E-15"
        ixz="-2.45565933576798E-07"
        iyy="2.56233006846258E-06"
        iyz="1.078452381831E-14"
        izz="2.40718051317747E-05" />
    </inertial>
    <visual>
      <origin
        xyz="0 0 0"
        rpy="0 0 0" />
      <geometry>
        <mesh
          filename="package://archie_description/meshes/camera_tilt.STL" />
      </geometry>
      <material
        name="">
        <color
          rgba="0.792156862745098 0.819607843137255 0.933333333333333 1" />
      </material>
    </visual>
    <collision>
      <origin
        xyz="0 0 0"
        rpy="0 0 0" />
      <geometry>
        <mesh
          filename="package://archie_description/meshes/camera_tilt.STL" />
      </geometry>
    </collision>
  </link>
  <joint
    name="camera_tilt_joint"
    type="revolute">
    <origin
      xyz="-0.0430000000000003 -0.000256393181805814 0.60585708860552"
      rpy="0.000423190833828544 -2.81011526104924E-16 2.84249707446941E-14" />
    <parent
      link="base" />
    <child
      link="camera_tilt" />
    <axis
      xyz="0 1 0" />
  </joint>
  <link
    name="camera">
    <inertial>
      <origin
        xyz="0.00288923128022706 5.89496325621441E-05 0.0145825271054898"
        rpy="0 0 0" />
      <mass
        value="0.0548652828266136" />
      <inertia
        ixx="6.99395203644299E-05"
        ixy="-9.65763568917195E-08"
        ixz="3.21146058326594E-08"
        iyy="6.26127942930752E-06"
        iyz="1.95459290349925E-09"
        izz="6.8843896362047E-05" />
    </inertial>
    <visual>
      <origin
        xyz="0 0 0"
        rpy="0 0 0" />
      <geometry>
        <mesh
          filename="package://archie_description/meshes/camera.STL" />
      </geometry>
      <material
        name="">
        <color
          rgba="0.792156862745098 0.819607843137255 0.933333333333333 1" />
      </material>
    </visual>
    <collision>
      <origin
        xyz="0 0 0"
        rpy="0 0 0" />
      <geometry>
        <mesh
          filename="package://archie_description/meshes/camera.STL" />
      </geometry>
    </collision>
  </link>
  <joint
    name="camera_joint"
    type="fixed">
    <origin
      xyz="0.0432049999999997 0 -0.00250000000000017"
      rpy="0 0 0" />
    <parent
      link="camera_tilt" />
    <child
      link="camera" />
    <axis
      xyz="0 0 0" />
  </joint>
</robot>